Workbook

Sheet START HERE
A1: Grade 7 ELA Pre/Post Assessment — Results Reporting Workbook
A4: What this workbook does
C5: You enter item-level scores. It computes reporting-category profiles, achievement levels, growth statistics, item difficulty, and ready-to-teach intervention groups — automatically, for every student.
A7: Do this, in this order
B8: 1. Roster | C8: Enter your students. Anything you type in a YELLOW cell is an input; everything else is a formula and should be left alone. Row 6 contains an example student — overwrite it.
B9: 2. Pre-Test Entry | C9: After administering Form A, enter the points earned on each item. Enter 0 for a wrong answer, not a blank. Blanks are treated as 'not yet tested'.
B10: 3. Student Report | C10: Read the profile. It is computed the moment you finish entering.
B11: 4. Intervention Groups | C11: Sort by column F. That column is each student's primary instructional group.
B12: 5. Post-Test Entry | C12: After administering Form B in the spring, enter scores the same way.
B13: 6. Class Dashboard | C13: Growth, effect size, and level movement for the whole class or by period.
A15: Cell colors
B16: Yellow | C16: You type here. These are the only cells you should edit.
B17: White / grey | C17: Formulas. Editing one breaks the report for that student.
B18: Blue text | C18: A value you may change deliberately (cut scores, thresholds) on the Settings sheet.
A20: Score entry rules
B21: Items 1-38 | C21: Enter the points earned: 0 or 1 for 1-point items; 0, 1, or 2 for 2-point items. The maximum for each item is shown in row 4 of the entry sheet.
B22: Item 39 (essay) | C22: Enter THREE separate trait scores: Q39_T1 (0-3), Q39_T2 (0-3), Q39_T3 (0-2). Half-points are allowed if you double-scored and averaged.
B23: Essay condition code | C23: If the essay could not be rubric-scored, leave the three trait cells BLANK and enter a code (A-E) in the Essay Cond Code column. See the scoring guide.
A25: Three things worth knowing before you report any of this
B26: Category scores are small | C26: A category rests on as few as 6 points. Treat a low category percent as a HYPOTHESIS to confirm against the student's actual work — never as a diagnosis on its own. The Student Report shows the items missed for exactly this reason.
B27: Not every gain is real | C27: The workbook computes a Reliable Change Index. A gain smaller than the reliable-change threshold on the Settings sheet may be measurement noise. Report small individual gains as class-level movement, not as student growth.
B28: Cut scores are provisional | C28: The achievement levels here were set by content review, not by a state standard-setting panel. They are instructional triage, NOT a prediction of a student's Georgia Milestones level. Replace them with locally derived cuts after your first full year.
A30: Sheets in this workbook
B31: Settings | C31: Cut scores, mastery thresholds, growth target, and the intervention lookup table. All editable.
B32: Roster | C32: Student names, class period, form order, and subgroup flags.
B33: Pre-Test Entry / Post-Test Entry | C33: Item-level score entry for Form A and Form B.
B34: Student Report | C34: One row per student: totals, levels, growth statistics, category profile, weakest areas, and a recommended instructional focus.
B35: Class Dashboard | C35: Class and period summaries, level distributions, category means, and effect size.
B36: Item Analysis | C36: Item difficulty (p-values), discrimination, pre/post change, Cronbach's alpha, and flags for items that are not working.
B37: Intervention Groups | C37: Mastery heat map plus each student's primary and secondary instructional group.
B38: Standards Coverage | C38: Which Grade 7 expectations this instrument does and does not measure.
B40: Source of truth | C40: Georgia's K-12 ELA Standards, Grade 7 (May 2023) · Georgia Milestones Grade 7 ELA Assessment Blueprint (August 2025) · Draft Grade 7 ELA Achievement Level Descriptors (October 2025) · Georgia Milestones Grade 7 Eight-Point, Three-Trait Writing Rubric (August 2026) · Grade 7 Classroom Peer Revision Guidance (February 2026).

Sheet Settings
A1: Settings — cut scores, thresholds, and the intervention lookup table | Y1: Helper: class-period filter used by the Class Dashboard | Z1: =IF('Class Dashboard'!$B$4="","*",'Class Dashboard'!$B$4)
A2: Blue values are editable. Every formula in this workbook reads from these cells, so changing one here updates every report.
A4: Achievement level cut scores (raw points out of 60)
A5: Developing Learner — minimum raw score | B5: 30 | D5: Below this score a student is a Beginning Learner. Default = 50% of 60.
A6: Proficient Learner — minimum raw score | B6: 39 | D6: Default = 65% of 60.
A7: Distinguished Learner — minimum raw score | B7: 49 | D7: Default = 82% of 60.
A8: Total points possible | B8: 60 | D8: Do not change unless you shorten the instrument.
A10: Category mastery thresholds (percent of category points)
A11: Mastered — minimum percent | B11: 0.8 | D11: At or above: maintain through spiral review.
A12: Approaching — minimum percent | B12: 0.6 | D12: Between this and Mastered: targeted small-group instruction. Below: explicit reteaching.
A14: Growth measurement
A15: Individual growth target (raw points) | B15: 9 | D15: Roughly half a standard deviation. Set BELOW the reliable-change threshold so it works as a goal, not a statistical claim.
A16: Assumed reliability (Cronbach's alpha) | B16: 0.85 | D16: Replace with the value computed on the Item Analysis sheet once you have a full class of data.
A17: Standard error of measurement (computed) | B17: =IFERROR(ROUND(STDEV('Student Report'!$D$6:$D$155)*SQRT(1-$B$16),2),"") | D17: SD of pre-test scores x SQRT(1 - reliability). Populates once pre-test data is entered.
A18: Reliable change threshold (raw points) | B18: =IFERROR(ROUND($B$17*SQRT(2)*1.96,1),"") | D18: A gain at or above this is statistically reliable for an individual student (95% confidence). Smaller gains may be measurement noise.
A20: Scoring quality (enter after double-scoring the essays)
A21: Essay double-scoring exact-agreement rate | D21: Below 70%, do not report individual essay growth — report class-level trait movement only.
A22: Number of essays double-scored | D22: Target: at least 20% of papers.
A24: Reporting category reference and intervention lookup
A25: Column C max points replicate the Georgia Milestones Grade 7 ELA blueprint exactly. Columns D and E feed the Recommended Focus column on the Student Report.
A27: Code | B27: Category | C27: Max pts | D27: Primary instructional focus | E27: Where to start
A28: I-CSS | B28: Interpreting — Context, Structure & Style | C28: 6 | D28: Author's purpose and audience; perspective, tone, and credibility; how structure and figurative language shape meaning | E28: Model 'why did the author build it this way?' on short texts. Standards 7.T.C.1.a, 7.T.C.2.a-b, 7.T.SS.1.a, 7.T.SS.2.a.
A29: I-TEC | B29: Interpreting — Techniques | C29: 16 | D29: Narrative, expository, argumentative, and poetic technique analysis; theme; claim and counterclaim; comparing two authors on one topic | E29: Largest category on the test (16 pts). Split by technique type before grouping — narrative gaps and argumentative gaps need different lessons.
A30: I-PRA | B30: Interpreting — Periods & Movements + Research | C30: 6 | D30: Myth and adaptation analysis; comparing fiction to an account of the same material; source credibility, relevance, and bibliographic information | E30: Pair every literary text with its source myth or historical account. Teach credibility as a two-part judgment: credible AND relevant to the question.
A31: I-LNG | B31: Interpreting — Language (Grammar & Vocabulary) | C31: 6 | D31: Context clues beyond the sentence; Greek and Latin roots; part of speech as a meaning clue; connotation; reading syntax | E31: Daily morphology routine plus 'read the next sentence' modeling for multiple-meaning words. Standards 7.L.V.2, 7.L.V.3, 7.L.GC.2.a.
A32: C-CSS | B32: Constructing — Context, Structure & Style | C32: 8 | D32: Introductions that establish a claim; cohesive structure; transitions that name relationships; style for a target audience; conclusions that finalize | E32: Peer Revision Task routine, Trait 1 guided questions. Start with claim-writing and conclusion-writing; transitions after.
A33: C-TEC | B33: Constructing — Techniques | C33: 10 | D33: Reasons that support the claim; evidence from MULTIPLE sources; elaboration in the student's own words; counterclaims; crediting sources | E33: Explicit evidence-to-elaboration instruction. Sentence stems: 'This matters because…' Reuse test items 27 and 28 as warm-ups.
A34: C-LNG | B34: Constructing — Language (Grammar & Vocabulary) | C34: 8 | D34: Sentence variety; consistent verb tense; active voice; misplaced and dangling modifiers; punctuation; precise word choice | E34: Sentence combining plus targeted GUM work on rows marked M at Grades 6-7. Standards 7.L.GC.2.b-d, 7.L.GC.1.
B35: TOTAL | C35: =SUM(C28:C34)
A37: Achievement level descriptors (Georgia Department of Education)
A38: Beginning Learner | D38: Does not yet demonstrate proficiency in the knowledge and skills necessary at this grade level. Needs substantial academic support to be prepared for the next grade level.
A39: Developing Learner | D39: Demonstrates partial proficiency. Needs additional academic support to ensure success in the next grade level.
A40: Proficient Learner | D40: Demonstrates proficiency. Prepared for the next grade level and on track for post-secondary readiness.
A41: Distinguished Learner | D41: Demonstrates advanced proficiency. Well prepared for the next grade level and for post-secondary readiness.

Sheet Roster
A1: Roster
A2: Every yellow cell is an input. Row 6 is an example — overwrite it with your first student. Student order here fixes the row order on every other sheet.
A3: ="Students on roster: "&COUNTA(C6:C155)
A5: Student ID | B5: Last Name | C5: First Name | D5: Class Period | E5: Form Order | F5: Accommodations | G5: EL | H5: SWD | I5: Gifted
A6: 7001 | B6: Example | C6: Student | D6: 1st | E6: A then B | F6: None | G6: N | H6: N | I6: N

Sheet Pre-Test Entry
A1: Pre-Test Entry — FORM A
A2: Enter POINTS EARNED for each item. Enter 0 for a wrong answer — a blank means 'not tested' and removes the student from the statistics. Row 3 shows the reporting category; row 4 shows the maximum points for the item.
A3: Category → | C3: I-TEC | D3: I-TEC | E3: I-LNG | F3: I-CSS | G3: I-TEC | H3: I-TEC | I3: I-TEC | J3: I-TEC | K3: I-PRA | L3: I-PRA | M3: I-CSS | N3: I-TEC | O3: I-TEC | P3: I-LNG | Q3: I-LNG | R3: I-CSS | S3: I-TEC | T3: I-TEC | U3: I-LNG | V3: I-CSS | W3: I-LNG | X3: I-TEC | Y3: I-PRA | Z3: I-PRA | AA3: C-CSS | AB3: C-TEC | AC3: C-TEC | AD3: C-TEC | AE3: C-TEC | AF3: C-CSS | AG3: C-CSS | AH3: C-LNG | AI3: C-LNG | AJ3: C-LNG | AK3: C-LNG | AL3: C-LNG | AM3: C-TEC | AN3: C-CSS | AO3: C-CSS | AP3: C-TEC | AQ3: C-LNG
A4: Max points → | C4: 1 | D4: 2 | E4: 1 | F4: 1 | G4: 1 | H4: 1 | I4: 2 | J4: 2 | K4: 1 | L4: 2 | M4: 1 | N4: 1 | O4: 1 | P4: 1 | Q4: 1 | R4: 2 | S4: 1 | T4: 2 | U4: 1 | V4: 2 | W4: 2 | X4: 2 | Y4: 1 | Z4: 2 | AA4: 1 | AB4: 1 | AC4: 2 | AD4: 2 | AE4: 1 | AF4: 2 | AG4: 1 | AH4: 1 | AI4: 2 | AJ4: 1 | AK4: 1 | AL4: 1 | AM4: 1 | AN4: 1 | AO4: 3 | AP4: 3 | AQ4: 2 | AS4: =SUM(C4:AQ4)
A5: Student ID | B5: Student Name | C5: Q1 | D5: Q2 | E5: Q3 | F5: Q4 | G5: Q5 | H5: Q6 | I5: Q7 | J5: Q8 | K5: Q9 | L5: Q10 | M5: Q11 | N5: Q12 | O5: Q13 | P5: Q14 | Q5: Q15 | R5: Q16 | S5: Q17 | T5: Q18 | U5: Q19 | V5: Q20 | W5: Q21 | X5: Q22 | Y5: Q23 | Z5: Q24 | AA5: Q25 | AB5: Q26 | AC5: Q27 | AD5: Q28 | AE5: Q29 | AF5: Q30 | AG5: Q31 | AH5: Q32 | AI5: Q33 | AJ5: Q34 | AK5: Q35 | AL5: Q36 | AM5: Q37 | AN5: Q38 | AO5: Q39_T1 | AP5: Q39_T2 | AQ5: Q39_T3 | AR5: Essay Cond Code | AS5: TOTAL
A6: =IF(Roster!$A6="","",Roster!$A6) | B6: =IF(Roster!$B6="","",Roster!$C6&" "&Roster!$B6) | AS6: =IF(COUNT(C6:AQ6)=0,"",SUM(C6:AQ6))
A7: =IF(Roster!$A7="","",Roster!$A7) | B7: =IF(Roster!$B7="","",Roster!$C7&" "&Roster!$B7) | AS7: =IF(COUNT(C7:AQ7)=0,"",SUM(C7:AQ7))
A8: =IF(Roster!$A8="","",Roster!$A8) | B8: =IF(Roster!$B8="","",Roster!$C8&" "&Roster!$B8) | AS8: =IF(COUNT(C8:AQ8)=0,"",SUM(C8:AQ8))
A9: =IF(Roster!$A9="","",Roster!$A9) | B9: =IF(Roster!$B9="","",Roster!$C9&" "&Roster!$B9) | AS9: =IF(COUNT(C9:AQ9)=0,"",SUM(C9:AQ9))
A10: =IF(Roster!$A10="","",Roster!$A10) | B10: =IF(Roster!$B10="","",Roster!$C10&" "&Roster!$B10) | AS10: =IF(COUNT(C10:AQ10)=0,"",SUM(C10:AQ10))
A11: =IF(Roster!$A11="","",Roster!$A11) | B11: =IF(Roster!$B11="","",Roster!$C11&" "&Roster!$B11) | AS11: =IF(COUNT(C11:AQ11)=0,"",SUM(C11:AQ11))
A12: =IF(Roster!$A12="","",Roster!$A12) | B12: =IF(Roster!$B12="","",Roster!$C12&" "&Roster!$B12) | AS12: =IF(COUNT(C12:AQ12)=0,"",SUM(C12:AQ12))
A13: =IF(Roster!$A13="","",Roster!$A13) | B13: =IF(Roster!$B13="","",Roster!$C13&" "&Roster!$B13) | AS13: =IF(COUNT(C13:AQ13)=0,"",SUM(C13:AQ13))
A14: =IF(Roster!$A14="","",Roster!$A14) | B14: =IF(Roster!$B14="","",Roster!$C14&" "&Roster!$B14) | AS14: =IF(COUNT(C14:AQ14)=0,"",SUM(C14:AQ14))
A15: =IF(Roster!$A15="","",Roster!$A15) | B15: =IF(Roster!$B15="","",Roster!$C15&" "&Roster!$B15) | AS15: =IF(COUNT(C15:AQ15)=0,"",SUM(C15:AQ15))
A16: =IF(Roster!$A16="","",Roster!$A16) | B16: =IF(Roster!$B16="","",Roster!$C16&" "&Roster!$B16) | AS16: =IF(COUNT(C16:AQ16)=0,"",SUM(C16:AQ16))
A17: =IF(Roster!$A17="","",Roster!$A17) | B17: =IF(Roster!$B17="","",Roster!$C17&" "&Roster!$B17) | AS17: =IF(COUNT(C17:AQ17)=0,"",SUM(C17:AQ17))
... A155: =IF(Roster!$A155="","",Roster!$A155) | B155: =IF(Roster!$B155="","",Roster!$C155&" "&Roster!$B155) | AS155: =IF(COUNT(C155:AQ155)=0,"",SUM(C155:AQ155))

Sheet Post-Test Entry
A1: Post-Test Entry — FORM B
A2: Enter POINTS EARNED for each item. Enter 0 for a wrong answer — a blank means 'not tested' and removes the student from the statistics. Row 3 shows the reporting category; row 4 shows the maximum points for the item.
A3: Category → | C3: I-TEC | D3: I-TEC | E3: I-LNG | F3: I-CSS | G3: I-TEC | H3: I-TEC | I3: I-TEC | J3: I-TEC | K3: I-PRA | L3: I-PRA | M3: I-CSS | N3: I-TEC | O3: I-TEC | P3: I-LNG | Q3: I-LNG | R3: I-CSS | S3: I-TEC | T3: I-TEC | U3: I-LNG | V3: I-CSS | W3: I-LNG | X3: I-TEC | Y3: I-PRA | Z3: I-PRA | AA3: C-CSS | AB3: C-TEC | AC3: C-TEC | AD3: C-TEC | AE3: C-TEC | AF3: C-CSS | AG3: C-CSS | AH3: C-LNG | AI3: C-LNG | AJ3: C-LNG | AK3: C-LNG | AL3: C-LNG | AM3: C-TEC | AN3: C-CSS | AO3: C-CSS | AP3: C-TEC | AQ3: C-LNG
A4: Max points → | C4: 1 | D4: 2 | E4: 1 | F4: 1 | G4: 1 | H4: 1 | I4: 2 | J4: 2 | K4: 1 | L4: 2 | M4: 1 | N4: 1 | O4: 1 | P4: 1 | Q4: 1 | R4: 2 | S4: 1 | T4: 2 | U4: 1 | V4: 2 | W4: 2 | X4: 2 | Y4: 1 | Z4: 2 | AA4: 1 | AB4: 1 | AC4: 2 | AD4: 2 | AE4: 1 | AF4: 2 | AG4: 1 | AH4: 1 | AI4: 2 | AJ4: 1 | AK4: 1 | AL4: 1 | AM4: 1 | AN4: 1 | AO4: 3 | AP4: 3 | AQ4: 2 | AS4: =SUM(C4:AQ4)
A5: Student ID | B5: Student Name | C5: Q1 | D5: Q2 | E5: Q3 | F5: Q4 | G5: Q5 | H5: Q6 | I5: Q7 | J5: Q8 | K5: Q9 | L5: Q10 | M5: Q11 | N5: Q12 | O5: Q13 | P5: Q14 | Q5: Q15 | R5: Q16 | S5: Q17 | T5: Q18 | U5: Q19 | V5: Q20 | W5: Q21 | X5: Q22 | Y5: Q23 | Z5: Q24 | AA5: Q25 | AB5: Q26 | AC5: Q27 | AD5: Q28 | AE5: Q29 | AF5: Q30 | AG5: Q31 | AH5: Q32 | AI5: Q33 | AJ5: Q34 | AK5: Q35 | AL5: Q36 | AM5: Q37 | AN5: Q38 | AO5: Q39_T1 | AP5: Q39_T2 | AQ5: Q39_T3 | AR5: Essay Cond Code | AS5: TOTAL
A6: =IF(Roster!$A6="","",Roster!$A6) | B6: =IF(Roster!$B6="","",Roster!$C6&" "&Roster!$B6) | AS6: =IF(COUNT(C6:AQ6)=0,"",SUM(C6:AQ6))
A7: =IF(Roster!$A7="","",Roster!$A7) | B7: =IF(Roster!$B7="","",Roster!$C7&" "&Roster!$B7) | AS7: =IF(COUNT(C7:AQ7)=0,"",SUM(C7:AQ7))
A8: =IF(Roster!$A8="","",Roster!$A8) | B8: =IF(Roster!$B8="","",Roster!$C8&" "&Roster!$B8) | AS8: =IF(COUNT(C8:AQ8)=0,"",SUM(C8:AQ8))
A9: =IF(Roster!$A9="","",Roster!$A9) | B9: =IF(Roster!$B9="","",Roster!$C9&" "&Roster!$B9) | AS9: =IF(COUNT(C9:AQ9)=0,"",SUM(C9:AQ9))
A10: =IF(Roster!$A10="","",Roster!$A10) | B10: =IF(Roster!$B10="","",Roster!$C10&" "&Roster!$B10) | AS10: =IF(COUNT(C10:AQ10)=0,"",SUM(C10:AQ10))
A11: =IF(Roster!$A11="","",Roster!$A11) | B11: =IF(Roster!$B11="","",Roster!$C11&" "&Roster!$B11) | AS11: =IF(COUNT(C11:AQ11)=0,"",SUM(C11:AQ11))
A12: =IF(Roster!$A12="","",Roster!$A12) | B12: =IF(Roster!$B12="","",Roster!$C12&" "&Roster!$B12) | AS12: =IF(COUNT(C12:AQ12)=0,"",SUM(C12:AQ12))
A13: =IF(Roster!$A13="","",Roster!$A13) | B13: =IF(Roster!$B13="","",Roster!$C13&" "&Roster!$B13) | AS13: =IF(COUNT(C13:AQ13)=0,"",SUM(C13:AQ13))
A14: =IF(Roster!$A14="","",Roster!$A14) | B14: =IF(Roster!$B14="","",Roster!$C14&" "&Roster!$B14) | AS14: =IF(COUNT(C14:AQ14)=0,"",SUM(C14:AQ14))
A15: =IF(Roster!$A15="","",Roster!$A15) | B15: =IF(Roster!$B15="","",Roster!$C15&" "&Roster!$B15) | AS15: =IF(COUNT(C15:AQ15)=0,"",SUM(C15:AQ15))
A16: =IF(Roster!$A16="","",Roster!$A16) | B16: =IF(Roster!$B16="","",Roster!$C16&" "&Roster!$B16) | AS16: =IF(COUNT(C16:AQ16)=0,"",SUM(C16:AQ16))
A17: =IF(Roster!$A17="","",Roster!$A17) | B17: =IF(Roster!$B17="","",Roster!$C17&" "&Roster!$B17) | AS17: =IF(COUNT(C17:AQ17)=0,"",SUM(C17:AQ17))
... A155: =IF(Roster!$A155="","",Roster!$A155) | B155: =IF(Roster!$B155="","",Roster!$C155&" "&Roster!$B155) | AS155: =IF(COUNT(C155:AQ155)=0,"",SUM(C155:AQ155))

Sheet Student Report
A1: Student Report — individual profiles, growth, and recommended focus
A2: Every cell on this sheet is computed. A blank row means no scores have been entered for that student yet. 'NEAR CUT' means the student's score is within one standard error of a level boundary — for those students, trust the category profile and your own classroom evidence, not the level label.
D3: PRE-TEST (Form A) | G3: POST-TEST (Form B) | J3: GROWTH | O3: CATEGORY % — PRE | V3: CATEGORY % — POST | AC3: CATEGORY CHANGE (percentage points) | AJ3: ACTION
O4: I-CSS | P4: I-TEC | Q4: I-PRA | R4: I-LNG | S4: C-CSS | T4: C-TEC | U4: C-LNG | V4: I-CSS | W4: I-TEC | X4: I-PRA | Y4: I-LNG | Z4: C-CSS | AA4: C-TEC | AB4: C-LNG | AC4: I-CSS | AD4: I-TEC | AE4: I-PRA | AF4: I-LNG | AG4: C-CSS | AH4: C-TEC | AI4: C-LNG
A5: Student ID | B5: Student Name | C5: Period | D5: Total | E5: % | F5: Level | G5: Total | H5: % | I5: Level | J5: Raw gain | K5: % of possible gain | L5: RCI | M5: Reliable change? | N5: Met target? | O5: I-CSS | P5: I-TEC | Q5: I-PRA | R5: I-LNG | S5: C-CSS | T5: C-TEC | U5: C-LNG | V5: I-CSS | W5: I-TEC | X5: I-PRA | Y5: I-LNG | Z5: C-CSS | AA5: C-TEC | AB5: C-LNG | AC5: I-CSS | AD5: I-TEC | AE5: I-PRA | AF5: I-LNG | AG5: C-CSS | AH5: C-TEC | AI5: C-LNG | AJ5: Weakest category | AK5: 2nd weakest | AL5: Near cut? | AM5: Essay flag | AN5: Recommended focus | AP5: helper: pre^2 | AQ5: helper: post^2
A6: =IF(Roster!$A6="","",Roster!$A6) | B6: =IF(Roster!$B6<>"",Roster!$C6&" "&Roster!$B6,"") | C6: =IF(Roster!$B6<>"",Roster!$D6,"") | D6: =IF(AND(Roster!$B6<>"",COUNT('Pre-Test Entry'!$C6:$AQ6)>0),'Pre-Test Entry'!$AS6,"") | E6: =IFERROR(D6/Settings!$B$8,"") | F6: =IF(D6="","",IF(D6>=Settings!$B$7,"Distinguished Learner",IF(D6>=Settings!$B$6,"Proficient Learner",IF(D6>=Settings!$B$5,"Developing Learner","Beginning Learner")))) | G6: =IF(AND(Roster!$B6<>"",COUNT('Post-Test Entry'!$C6:$AQ6)>0),'Post-Test Entry'!$AS6,"") | H6: =IFERROR(G6/Settings!$B$8,"") | I6: =IF(G6="","",IF(G6>=Settings!$B$7,"Distinguished Learner",IF(G6>=Settings!$B$6,"Proficient Learner",IF(G6>=Settings!$B$5,"Developing Learner","Beginning Learner")))) | J6: =IF(OR(D6="",G6=""),"",G6-D6) | K6: =IFERROR(IF(OR(J6="",J6<=0),"",(G6-D6)/(Settings!$B$8-D6)),"") | L6: =IFERROR(IF(J6="","",(G6-D6)/(Settings!$B$17*SQRT(2))),"") | M6: =IF(L6="","",IF(ABS(L6)>=1.96,"Yes","No")) | N6: =IF(J6="","",IF(J6>=Settings!$B$15,"Yes","No")) | O6: =IFERROR(IF($D6="","",SUMIF('Pre-Test Entry'!$C$3:$AQ$3,Settings!$A$28,'Pre-Test Entry'!$C6:$AQ6)/Settings!$C$28),"") | P6: =IFERROR(IF($D6="","",SUMIF('Pre-Test Entry'!$C$3:$AQ$3,Settings!$A$29,'Pre-Test Entry'!$C6:$AQ6)/Settings!$C$29),"") | Q6: =IFERROR(IF($D6="","",SUMIF('Pre-Test Entry'!$C$3:$AQ$3,Settings!$A$30,'Pre-Test Entry'!$C6:$AQ6)/Settings!$C$30),"") | R6: =IFERROR(IF($D6="","",SUMIF('Pre-Test Entry'!$C$3:$AQ$3,Settings!$A$31,'Pre-Test Entry'!$C6:$AQ6)/Settings!$C$31),"") | S6: =IFERROR(IF($D6="","",SUMIF('Pre-Test Entry'!$C$3:$AQ$3,Settings!$A$32,'Pre-Test Entry'!$C6:$AQ6)/Settings!$C$32),"") | T6: =IFERROR(IF($D6="","",SUMIF('Pre-Test Entry'!$C$3:$AQ$3,Settings!$A$33,'Pre-Test Entry'!$C6:$AQ6)/Settings!$C$33),"") | U6: =IFERROR(IF($D6="","",SUMIF('Pre-Test Entry'!$C$3:$AQ$3,Settings!$A$34,'Pre-Test Entry'!$C6:$AQ6)/Settings!$C$34),"") | V6: =IFERROR(IF($G6="","",SUMIF('Post-Test Entry'!$C$3:$AQ$3,Settings!$A$28,'Post-Test Entry'!$C6:$AQ6)/Settings!$C$28),"") | W6: =IFERROR(IF($G6="","",SUMIF('Post-Test Entry'!$C$3:$AQ$3,Settings!$A$29,'Post-Test Entry'!$C6:$AQ6)/Settings!$C$29),"") | X6: =IFERROR(IF($G6="","",SUMIF('Post-Test Entry'!$C$3:$AQ$3,Settings!$A$30,'Post-Test Entry'!$C6:$AQ6)/Settings!$C$30),"") | Y6: =IFERROR(IF($G6="","",SUMIF('Post-Test Entry'!$C$3:$AQ$3,Settings!$A$31,'Post-Test Entry'!$C6:$AQ6)/Settings!$C$31),"") | Z6: =IFERROR(IF($G6="","",SUMIF('Post-Test Entry'!$C$3:$AQ$3,Settings!$A$32,'Post-Test Entry'!$C6:$AQ6)/Settings!$C$32),"") | AA6: =IFERROR(IF($G6="","",SUMIF('Post-Test Entry'!$C$3:$AQ$3,Settings!$A$33,'Post-Test Entry'!$C6:$AQ6)/Settings!$C$33),"") | AB6: =IFERROR(IF($G6="","",SUMIF('Post-Test Entry'!$C$3:$AQ$3,Settings!$A$34,'Post-Test Entry'!$C6:$AQ6)/Settings!$C$34),"") | AC6: =IF(OR(O6="",V6=""),"",V6-O6) | AD6: =IF(OR(P6="",W6=""),"",W6-P6) | AE6: =IF(OR(Q6="",X6=""),"",X6-Q6) | AF6: =IF(OR(R6="",Y6=""),"",Y6-R6) | AG6: =IF(OR(S6="",Z6=""),"",Z6-S6) | AH6: =IF(OR(T6="",AA6=""),"",AA6-T6) | AI6: =IF(OR(U6="",AB6=""),"",AB6-U6) | AJ6: =IFERROR(IF($G6<>"",INDEX($V$4:$AB$4,MATCH(MIN($V6:$AB6),$V6:$AB6,0)),IF($D6<>"",INDEX($O$4:$U$4,MATCH(MIN($O6:$U6),$O6:$U6,0)),"")),"") | AK6: =IFERROR(IF($G6<>"",INDEX($V$4:$AB$4,MATCH(SMALL($V6:$AB6,2),$V6:$AB6,0)),IF($D6<>"",INDEX($O$4:$U$4,MATCH(SMALL($O6:$U6,2),$O6:$U6,0)),"")),"") | AL6: =IF(OR(G6="",Settings!$B$17=""),"",IF(OR(ABS(G6-Settings!$B$5)<=Settings!$B$17,ABS(G6-Settings!$B$6)<=Settings!$B$17,ABS(G6-Settings!$B$7)<=Settings!$B$17),"NEAR CUT","")) | AM6: =IF('Post-Test Entry'!$AR6<>"","Post essay: code "&'Post-Test Entry'!$AR6,IF('Pre-Test Entry'!$AR6<>"","Pre essay: code "&'Pre-Test Entry'!$AR6,"")) | AN6: =IFERROR(IF($AJ6="","",INDEX(Settings!$D$28:$D$34,MATCH($AJ6,Settings!$A$28:$A$34,0))),"") | AP6: =IF(D6="","",D6^2) | AQ6: =IF(G6="","",G6^2)
A7: =IF(Roster!$A7="","",Roster!$A7) | B7: =IF(Roster!$B7<>"",Roster!$C7&" "&Roster!$B7,"") | C7: =IF(Roster!$B7<>"",Roster!$D7,"") | D7: =IF(AND(Roster!$B7<>"",COUNT('Pre-Test Entry'!$C7:$AQ7)>0),'Pre-Test Entry'!$AS7,"") | E7: =IFERROR(D7/Settings!$B$8,"") | F7: =IF(D7="","",IF(D7>=Settings!$B$7,"Distinguished Learner",IF(D7>=Settings!$B$6,"Proficient Learner",IF(D7>=Settings!$B$5,"Developing Learner","Beginning Learner")))) | G7: =IF(AND(Roster!$B7<>"",COUNT('Post-Test Entry'!$C7:$AQ7)>0),'Post-Test Entry'!$AS7,"") | H7: =IFERROR(G7/Settings!$B$8,"") | I7: =IF(G7="","",IF(G7>=Settings!$B$7,"Distinguished Learner",IF(G7>=Settings!$B$6,"Proficient Learner",IF(G7>=Settings!$B$5,"Developing Learner","Beginning Learner")))) | J7: =IF(OR(D7="",G7=""),"",G7-D7) | K7: =IFERROR(IF(OR(J7="",J7<=0),"",(G7-D7)/(Settings!$B$8-D7)),"") | L7: =IFERROR(IF(J7="","",(G7-D7)/(Settings!$B$17*SQRT(2))),"") | M7: =IF(L7="","",IF(ABS(L7)>=1.96,"Yes","No")) | N7: =IF(J7="","",IF(J7>=Settings!$B$15,"Yes","No")) | O7: =IFERROR(IF($D7="","",SUMIF('Pre-Test Entry'!$C$3:$AQ$3,Settings!$A$28,'Pre-Test Entry'!$C7:$AQ7)/Settings!$C$28),"") | P7: =IFERROR(IF($D7="","",SUMIF('Pre-Test Entry'!$C$3:$AQ$3,Settings!$A$29,'Pre-Test Entry'!$C7:$AQ7)/Settings!$C$29),"") | Q7: =IFERROR(IF($D7="","",SUMIF('Pre-Test Entry'!$C$3:$AQ$3,Settings!$A$30,'Pre-Test Entry'!$C7:$AQ7)/Settings!$C$30),"") | R7: =IFERROR(IF($D7="","",SUMIF('Pre-Test Entry'!$C$3:$AQ$3,Settings!$A$31,'Pre-Test Entry'!$C7:$AQ7)/Settings!$C$31),"") | S7: =IFERROR(IF($D7="","",SUMIF('Pre-Test Entry'!$C$3:$AQ$3,Settings!$A$32,'Pre-Test Entry'!$C7:$AQ7)/Settings!$C$32),"") | T7: =IFERROR(IF($D7="","",SUMIF('Pre-Test Entry'!$C$3:$AQ$3,Settings!$A$33,'Pre-Test Entry'!$C7:$AQ7)/Settings!$C$33),"") | U7: =IFERROR(IF($D7="","",SUMIF('Pre-Test Entry'!$C$3:$AQ$3,Settings!$A$34,'Pre-Test Entry'!$C7:$AQ7)/Settings!$C$34),"") | V7: =IFERROR(IF($G7="","",SUMIF('Post-Test Entry'!$C$3:$AQ$3,Settings!$A$28,'Post-Test Entry'!$C7:$AQ7)/Settings!$C$28),"") | W7: =IFERROR(IF($G7="","",SUMIF('Post-Test Entry'!$C$3:$AQ$3,Settings!$A$29,'Post-Test Entry'!$C7:$AQ7)/Settings!$C$29),"") | X7: =IFERROR(IF($G7="","",SUMIF('Post-Test Entry'!$C$3:$AQ$3,Settings!$A$30,'Post-Test Entry'!$C7:$AQ7)/Settings!$C$30),"") | Y7: =IFERROR(IF($G7="","",SUMIF('Post-Test Entry'!$C$3:$AQ$3,Settings!$A$31,'Post-Test Entry'!$C7:$AQ7)/Settings!$C$31),"") | Z7: =IFERROR(IF($G7="","",SUMIF('Post-Test Entry'!$C$3:$AQ$3,Settings!$A$32,'Post-Test Entry'!$C7:$AQ7)/Settings!$C$32),"") | AA7: =IFERROR(IF($G7="","",SUMIF('Post-Test Entry'!$C$3:$AQ$3,Settings!$A$33,'Post-Test Entry'!$C7:$AQ7)/Settings!$C$33),"") | AB7: =IFERROR(IF($G7="","",SUMIF('Post-Test Entry'!$C$3:$AQ$3,Settings!$A$34,'Post-Test Entry'!$C7:$AQ7)/Settings!$C$34),"") | AC7: =IF(OR(O7="",V7=""),"",V7-O7) | AD7: =IF(OR(P7="",W7=""),"",W7-P7) | AE7: =IF(OR(Q7="",X7=""),"",X7-Q7) | AF7: =IF(OR(R7="",Y7=""),"",Y7-R7) | AG7: =IF(OR(S7="",Z7=""),"",Z7-S7) | AH7: =IF(OR(T7="",AA7=""),"",AA7-T7) | AI7: =IF(OR(U7="",AB7=""),"",AB7-U7) | AJ7: =IFERROR(IF($G7<>"",INDEX($V$4:$AB$4,MATCH(MIN($V7:$AB7),$V7:$AB7,0)),IF($D7<>"",INDEX($O$4:$U$4,MATCH(MIN($O7:$U7),$O7:$U7,0)),"")),"") | AK7: =IFERROR(IF($G7<>"",INDEX($V$4:$AB$4,MATCH(SMALL($V7:$AB7,2),$V7:$AB7,0)),IF($D7<>"",INDEX($O$4:$U$4,MATCH(SMALL($O7:$U7,2),$O7:$U7,0)),"")),"") | AL7: =IF(OR(G7="",Settings!$B$17=""),"",IF(OR(ABS(G7-Settings!$B$5)<=Settings!$B$17,ABS(G7-Settings!$B$6)<=Settings!$B$17,ABS(G7-Settings!$B$7)<=Settings!$B$17),"NEAR CUT","")) | AM7: =IF('Post-Test Entry'!$AR7<>"","Post essay: code "&'Post-Test Entry'!$AR7,IF('Pre-Test Entry'!$AR7<>"","Pre essay: code "&'Pre-Test Entry'!$AR7,"")) | AN7: =IFERROR(IF($AJ7="","",INDEX(Settings!$D$28:$D$34,MATCH($AJ7,Settings!$A$28:$A$34,0))),"") | AP7: =IF(D7="","",D7^2) | AQ7: =IF(G7="","",G7^2)
A8: =IF(Roster!$A8="","",Roster!$A8) | B8: =IF(Roster!$B8<>"",Roster!$C8&" "&Roster!$B8,"") | C8: =IF(Roster!$B8<>"",Roster!$D8,"") | D8: =IF(AND(Roster!$B8<>"",COUNT('Pre-Test Entry'!$C8:$AQ8)>0),'Pre-Test Entry'!$AS8,"") | E8: =IFERROR(D8/Settings!$B$8,"") | F8: =IF(D8="","",IF(D8>=Settings!$B$7,"Distinguished Learner",IF(D8>=Settings!$B$6,"Proficient Learner",IF(D8>=Settings!$B$5,"Developing Learner","Beginning Learner")))) | G8: =IF(AND(Roster!$B8<>"",COUNT('Post-Test Entry'!$C8:$AQ8)>0),'Post-Test Entry'!$AS8,"") | H8: =IFERROR(G8/Settings!$B$8,"") | I8: =IF(G8="","",IF(G8>=Settings!$B$7,"Distinguished Learner",IF(G8>=Settings!$B$6,"Proficient Learner",IF(G8>=Settings!$B$5,"Developing Learner","Beginning Learner")))) | J8: =IF(OR(D8="",G8=""),"",G8-D8) | K8: =IFERROR(IF(OR(J8="",J8<=0),"",(G8-D8)/(Settings!$B$8-D8)),"") | L8: =IFERROR(IF(J8="","",(G8-D8)/(Settings!$B$17*SQRT(2))),"") | M8: =IF(L8="","",IF(ABS(L8)>=1.96,"Yes","No")) | N8: =IF(J8="","",IF(J8>=Settings!$B$15,"Yes","No")) | O8: =IFERROR(IF($D8="","",SUMIF('Pre-Test Entry'!$C$3:$AQ$3,Settings!$A$28,'Pre-Test Entry'!$C8:$AQ8)/Settings!$C$28),"") | P8: =IFERROR(IF($D8="","",SUMIF('Pre-Test Entry'!$C$3:$AQ$3,Settings!$A$29,'Pre-Test Entry'!$C8:$AQ8)/Settings!$C$29),"") | Q8: =IFERROR(IF($D8="","",SUMIF('Pre-Test Entry'!$C$3:$AQ$3,Settings!$A$30,'Pre-Test Entry'!$C8:$AQ8)/Settings!$C$30),"") | R8: =IFERROR(IF($D8="","",SUMIF('Pre-Test Entry'!$C$3:$AQ$3,Settings!$A$31,'Pre-Test Entry'!$C8:$AQ8)/Settings!$C$31),"") | S8: =IFERROR(IF($D8="","",SUMIF('Pre-Test Entry'!$C$3:$AQ$3,Settings!$A$32,'Pre-Test Entry'!$C8:$AQ8)/Settings!$C$32),"") | T8: =IFERROR(IF($D8="","",SUMIF('Pre-Test Entry'!$C$3:$AQ$3,Settings!$A$33,'Pre-Test Entry'!$C8:$AQ8)/Settings!$C$33),"") | U8: =IFERROR(IF($D8="","",SUMIF('Pre-Test Entry'!$C$3:$AQ$3,Settings!$A$34,'Pre-Test Entry'!$C8:$AQ8)/Settings!$C$34),"") | V8: =IFERROR(IF($G8="","",SUMIF('Post-Test Entry'!$C$3:$AQ$3,Settings!$A$28,'Post-Test Entry'!$C8:$AQ8)/Settings!$C$28),"") | W8: =IFERROR(IF($G8="","",SUMIF('Post-Test Entry'!$C$3:$AQ$3,Settings!$A$29,'Post-Test Entry'!$C8:$AQ8)/Settings!$C$29),"") | X8: =IFERROR(IF($G8="","",SUMIF('Post-Test Entry'!$C$3:$AQ$3,Settings!$A$30,'Post-Test Entry'!$C8:$AQ8)/Settings!$C$30),"") | Y8: =IFERROR(IF($G8="","",SUMIF('Post-Test Entry'!$C$3:$AQ$3,Settings!$A$31,'Post-Test Entry'!$C8:$AQ8)/Settings!$C$31),"") | Z8: =IFERROR(IF($G8="","",SUMIF('Post-Test Entry'!$C$3:$AQ$3,Settings!$A$32,'Post-Test Entry'!$C8:$AQ8)/Settings!$C$32),"") | AA8: =IFERROR(IF($G8="","",SUMIF('Post-Test Entry'!$C$3:$AQ$3,Settings!$A$33,'Post-Test Entry'!$C8:$AQ8)/Settings!$C$33),"") | AB8: =IFERROR(IF($G8="","",SUMIF('Post-Test Entry'!$C$3:$AQ$3,Settings!$A$34,'Post-Test Entry'!$C8:$AQ8)/Settings!$C$34),"") | AC8: =IF(OR(O8="",V8=""),"",V8-O8) | AD8: =IF(OR(P8="",W8=""),"",W8-P8) | AE8: =IF(OR(Q8="",X8=""),"",X8-Q8) | AF8: =IF(OR(R8="",Y8=""),"",Y8-R8) | AG8: =IF(OR(S8="",Z8=""),"",Z8-S8) | AH8: =IF(OR(T8="",AA8=""),"",AA8-T8) | AI8: =IF(OR(U8="",AB8=""),"",AB8-U8) | AJ8: =IFERROR(IF($G8<>"",INDEX($V$4:$AB$4,MATCH(MIN($V8:$AB8),$V8:$AB8,0)),IF($D8<>"",INDEX($O$4:$U$4,MATCH(MIN($O8:$U8),$O8:$U8,0)),"")),"") | AK8: =IFERROR(IF($G8<>"",INDEX($V$4:$AB$4,MATCH(SMALL($V8:$AB8,2),$V8:$AB8,0)),IF($D8<>"",INDEX($O$4:$U$4,MATCH(SMALL($O8:$U8,2),$O8:$U8,0)),"")),"") | AL8: =IF(OR(G8="",Settings!$B$17=""),"",IF(OR(ABS(G8-Settings!$B$5)<=Settings!$B$17,ABS(G8-Settings!$B$6)<=Settings!$B$17,ABS(G8-Settings!$B$7)<=Settings!$B$17),"NEAR CUT","")) | AM8: =IF('Post-Test Entry'!$AR8<>"","Post essay: code "&'Post-Test Entry'!$AR8,IF('Pre-Test Entry'!$AR8<>"","Pre essay: code "&'Pre-Test Entry'!$AR8,"")) | AN8: =IFERROR(IF($AJ8="","",INDEX(Settings!$D$28:$D$34,MATCH($AJ8,Settings!$A$28:$A$34,0))),"") | AP8: =IF(D8="","",D8^2) | AQ8: =IF(G8="","",G8^2)
A9: =IF(Roster!$A9="","",Roster!$A9) | B9: =IF(Roster!$B9<>"",Roster!$C9&" "&Roster!$B9,"") | C9: =IF(Roster!$B9<>"",Roster!$D9,"") | D9: =IF(AND(Roster!$B9<>"",COUNT('Pre-Test Entry'!$C9:$AQ9)>0),'Pre-Test Entry'!$AS9,"") | E9: =IFERROR(D9/Settings!$B$8,"") | F9: =IF(D9="","",IF(D9>=Settings!$B$7,"Distinguished Learner",IF(D9>=Settings!$B$6,"Proficient Learner",IF(D9>=Settings!$B$5,"Developing Learner","Beginning Learner")))) | G9: =IF(AND(Roster!$B9<>"",COUNT('Post-Test Entry'!$C9:$AQ9)>0),'Post-Test Entry'!$AS9,"") | H9: =IFERROR(G9/Settings!$B$8,"") | I9: =IF(G9="","",IF(G9>=Settings!$B$7,"Distinguished Learner",IF(G9>=Settings!$B$6,"Proficient Learner",IF(G9>=Settings!$B$5,"Developing Learner","Beginning Learner")))) | J9: =IF(OR(D9="",G9=""),"",G9-D9) | K9: =IFERROR(IF(OR(J9="",J9<=0),"",(G9-D9)/(Settings!$B$8-D9)),"") | L9: =IFERROR(IF(J9="","",(G9-D9)/(Settings!$B$17*SQRT(2))),"") | M9: =IF(L9="","",IF(ABS(L9)>=1.96,"Yes","No")) | N9: =IF(J9="","",IF(J9>=Settings!$B$15,"Yes","No")) | O9: =IFERROR(IF($D9="","",SUMIF('Pre-Test Entry'!$C$3:$AQ$3,Settings!$A$28,'Pre-Test Entry'!$C9:$AQ9)/Settings!$C$28),"") | P9: =IFERROR(IF($D9="","",SUMIF('Pre-Test Entry'!$C$3:$AQ$3,Settings!$A$29,'Pre-Test Entry'!$C9:$AQ9)/Settings!$C$29),"") | Q9: =IFERROR(IF($D9="","",SUMIF('Pre-Test Entry'!$C$3:$AQ$3,Settings!$A$30,'Pre-Test Entry'!$C9:$AQ9)/Settings!$C$30),"") | R9: =IFERROR(IF($D9="","",SUMIF('Pre-Test Entry'!$C$3:$AQ$3,Settings!$A$31,'Pre-Test Entry'!$C9:$AQ9)/Settings!$C$31),"") | S9: =IFERROR(IF($D9="","",SUMIF('Pre-Test Entry'!$C$3:$AQ$3,Settings!$A$32,'Pre-Test Entry'!$C9:$AQ9)/Settings!$C$32),"") | T9: =IFERROR(IF($D9="","",SUMIF('Pre-Test Entry'!$C$3:$AQ$3,Settings!$A$33,'Pre-Test Entry'!$C9:$AQ9)/Settings!$C$33),"") | U9: =IFERROR(IF($D9="","",SUMIF('Pre-Test Entry'!$C$3:$AQ$3,Settings!$A$34,'Pre-Test Entry'!$C9:$AQ9)/Settings!$C$34),"") | V9: =IFERROR(IF($G9="","",SUMIF('Post-Test Entry'!$C$3:$AQ$3,Settings!$A$28,'Post-Test Entry'!$C9:$AQ9)/Settings!$C$28),"") | W9: =IFERROR(IF($G9="","",SUMIF('Post-Test Entry'!$C$3:$AQ$3,Settings!$A$29,'Post-Test Entry'!$C9:$AQ9)/Settings!$C$29),"") | X9: =IFERROR(IF($G9="","",SUMIF('Post-Test Entry'!$C$3:$AQ$3,Settings!$A$30,'Post-Test Entry'!$C9:$AQ9)/Settings!$C$30),"") | Y9: =IFERROR(IF($G9="","",SUMIF('Post-Test Entry'!$C$3:$AQ$3,Settings!$A$31,'Post-Test Entry'!$C9:$AQ9)/Settings!$C$31),"") | Z9: =IFERROR(IF($G9="","",SUMIF('Post-Test Entry'!$C$3:$AQ$3,Settings!$A$32,'Post-Test Entry'!$C9:$AQ9)/Settings!$C$32),"") | AA9: =IFERROR(IF($G9="","",SUMIF('Post-Test Entry'!$C$3:$AQ$3,Settings!$A$33,'Post-Test Entry'!$C9:$AQ9)/Settings!$C$33),"") | AB9: =IFERROR(IF($G9="","",SUMIF('Post-Test Entry'!$C$3:$AQ$3,Settings!$A$34,'Post-Test Entry'!$C9:$AQ9)/Settings!$C$34),"") | AC9: =IF(OR(O9="",V9=""),"",V9-O9) | AD9: =IF(OR(P9="",W9=""),"",W9-P9) | AE9: =IF(OR(Q9="",X9=""),"",X9-Q9) | AF9: =IF(OR(R9="",Y9=""),"",Y9-R9) | AG9: =IF(OR(S9="",Z9=""),"",Z9-S9) | AH9: =IF(OR(T9="",AA9=""),"",AA9-T9) | AI9: =IF(OR(U9="",AB9=""),"",AB9-U9) | AJ9: =IFERROR(IF($G9<>"",INDEX($V$4:$AB$4,MATCH(MIN($V9:$AB9),$V9:$AB9,0)),IF($D9<>"",INDEX($O$4:$U$4,MATCH(MIN($O9:$U9),$O9:$U9,0)),"")),"") | AK9: =IFERROR(IF($G9<>"",INDEX($V$4:$AB$4,MATCH(SMALL($V9:$AB9,2),$V9:$AB9,0)),IF($D9<>"",INDEX($O$4:$U$4,MATCH(SMALL($O9:$U9,2),$O9:$U9,0)),"")),"") | AL9: =IF(OR(G9="",Settings!$B$17=""),"",IF(OR(ABS(G9-Settings!$B$5)<=Settings!$B$17,ABS(G9-Settings!$B$6)<=Settings!$B$17,ABS(G9-Settings!$B$7)<=Settings!$B$17),"NEAR CUT","")) | AM9: =IF('Post-Test Entry'!$AR9<>"","Post essay: code "&'Post-Test Entry'!$AR9,IF('Pre-Test Entry'!$AR9<>"","Pre essay: code "&'Pre-Test Entry'!$AR9,"")) | AN9: =IFERROR(IF($AJ9="","",INDEX(Settings!$D$28:$D$34,MATCH($AJ9,Settings!$A$28:$A$34,0))),"") | AP9: =IF(D9="","",D9^2) | AQ9: =IF(G9="","",G9^2)
A10: =IF(Roster!$A10="","",Roster!$A10) | B10: =IF(Roster!$B10<>"",Roster!$C10&" "&Roster!$B10,"") | C10: =IF(Roster!$B10<>"",Roster!$D10,"") | D10: =IF(AND(Roster!$B10<>"",COUNT('Pre-Test Entry'!$C10:$AQ10)>0),'Pre-Test Entry'!$AS10,"") | E10: =IFERROR(D10/Settings!$B$8,"") | F10: =IF(D10="","",IF(D10>=Settings!$B$7,"Distinguished Learner",IF(D10>=Settings!$B$6,"Proficient Learner",IF(D10>=Settings!$B$5,"Developing Learner","Beginning Learner")))) | G10: =IF(AND(Roster!$B10<>"",COUNT('Post-Test Entry'!$C10:$AQ10)>0),'Post-Test Entry'!$AS10,"") | H10: =IFERROR(G10/Settings!$B$8,"") | I10: =IF(G10="","",IF(G10>=Settings!$B$7,"Distinguished Learner",IF(G10>=Settings!$B$6,"Proficient Learner",IF(G10>=Settings!$B$5,"Developing Learner","Beginning Learner")))) | J10: =IF(OR(D10="",G10=""),"",G10-D10) | K10: =IFERROR(IF(OR(J10="",J10<=0),"",(G10-D10)/(Settings!$B$8-D10)),"") | L10: =IFERROR(IF(J10="","",(G10-D10)/(Settings!$B$17*SQRT(2))),"") | M10: =IF(L10="","",IF(ABS(L10)>=1.96,"Yes","No")) | N10: =IF(J10="","",IF(J10>=Settings!$B$15,"Yes","No")) | O10: =IFERROR(IF($D10="","",SUMIF('Pre-Test Entry'!$C$3:$AQ$3,Settings!$A$28,'Pre-Test Entry'!$C10:$AQ10)/Settings!$C$28),"") | P10: =IFERROR(IF($D10="","",SUMIF('Pre-Test Entry'!$C$3:$AQ$3,Settings!$A$29,'Pre-Test Entry'!$C10:$AQ10)/Settings!$C$29),"") | Q10: =IFERROR(IF($D10="","",SUMIF('Pre-Test Entry'!$C$3:$AQ$3,Settings!$A$30,'Pre-Test Entry'!$C10:$AQ10)/Settings!$C$30),"") | R10: =IFERROR(IF($D10="","",SUMIF('Pre-Test Entry'!$C$3:$AQ$3,Settings!$A$31,'Pre-Test Entry'!$C10:$AQ10)/Settings!$C$31),"") | S10: =IFERROR(IF($D10="","",SUMIF('Pre-Test Entry'!$C$3:$AQ$3,Settings!$A$32,'Pre-Test Entry'!$C10:$AQ10)/Settings!$C$32),"") | T10: =IFERROR(IF($D10="","",SUMIF('Pre-Test Entry'!$C$3:$AQ$3,Settings!$A$33,'Pre-Test Entry'!$C10:$AQ10)/Settings!$C$33),"") | U10: =IFERROR(IF($D10="","",SUMIF('Pre-Test Entry'!$C$3:$AQ$3,Settings!$A$34,'Pre-Test Entry'!$C10:$AQ10)/Settings!$C$34),"") | V10: =IFERROR(IF($G10="","",SUMIF('Post-Test Entry'!$C$3:$AQ$3,Settings!$A$28,'Post-Test Entry'!$C10:$AQ10)/Settings!$C$28),"") | W10: =IFERROR(IF($G10="","",SUMIF('Post-Test Entry'!$C$3:$AQ$3,Settings!$A$29,'Post-Test Entry'!$C10:$AQ10)/Settings!$C$29),"") | X10: =IFERROR(IF($G10="","",SUMIF('Post-Test Entry'!$C$3:$AQ$3,Settings!$A$30,'Post-Test Entry'!$C10:$AQ10)/Settings!$C$30),"") | Y10: =IFERROR(IF($G10="","",SUMIF('Post-Test Entry'!$C$3:$AQ$3,Settings!$A$31,'Post-Test Entry'!$C10:$AQ10)/Settings!$C$31),"") | Z10: =IFERROR(IF($G10="","",SUMIF('Post-Test Entry'!$C$3:$AQ$3,Settings!$A$32,'Post-Test Entry'!$C10:$AQ10)/Settings!$C$32),"") | AA10: =IFERROR(IF($G10="","",SUMIF('Post-Test Entry'!$C$3:$AQ$3,Settings!$A$33,'Post-Test Entry'!$C10:$AQ10)/Settings!$C$33),"") | AB10: =IFERROR(IF($G10="","",SUMIF('Post-Test Entry'!$C$3:$AQ$3,Settings!$A$34,'Post-Test Entry'!$C10:$AQ10)/Settings!$C$34),"") | AC10: =IF(OR(O10="",V10=""),"",V10-O10) | AD10: =IF(OR(P10="",W10=""),"",W10-P10) | AE10: =IF(OR(Q10="",X10=""),"",X10-Q10) | AF10: =IF(OR(R10="",Y10=""),"",Y10-R10) | AG10: =IF(OR(S10="",Z10=""),"",Z10-S10) | AH10: =IF(OR(T10="",AA10=""),"",AA10-T10) | AI10: =IF(OR(U10="",AB10=""),"",AB10-U10) | AJ10: =IFERROR(IF($G10<>"",INDEX($V$4:$AB$4,MATCH(MIN($V10:$AB10),$V10:$AB10,0)),IF($D10<>"",INDEX($O$4:$U$4,MATCH(MIN($O10:$U10),$O10:$U10,0)),"")),"") | AK10: =IFERROR(IF($G10<>"",INDEX($V$4:$AB$4,MATCH(SMALL($V10:$AB10,2),$V10:$AB10,0)),IF($D10<>"",INDEX($O$4:$U$4,MATCH(SMALL($O10:$U10,2),$O10:$U10,0)),"")),"") | AL10: =IF(OR(G10="",Settings!$B$17=""),"",IF(OR(ABS(G10-Settings!$B$5)<=Settings!$B$17,ABS(G10-Settings!$B$6)<=Settings!$B$17,ABS(G10-Settings!$B$7)<=Settings!$B$17),"NEAR CUT","")) | AM10: =IF('Post-Test Entry'!$AR10<>"","Post essay: code "&'Post-Test Entry'!$AR10,IF('Pre-Test Entry'!$AR10<>"","Pre essay: code "&'Pre-Test Entry'!$AR10,"")) | AN10: =IFERROR(IF($AJ10="","",INDEX(Settings!$D$28:$D$34,MATCH($AJ10,Settings!$A$28:$A$34,0))),"") | AP10: =IF(D10="","",D10^2) | AQ10: =IF(G10="","",G10^2)
A11: =IF(Roster!$A11="","",Roster!$A11) | B11: =IF(Roster!$B11<>"",Roster!$C11&" "&Roster!$B11,"") | C11: =IF(Roster!$B11<>"",Roster!$D11,"") | D11: =IF(AND(Roster!$B11<>"",COUNT('Pre-Test Entry'!$C11:$AQ11)>0),'Pre-Test Entry'!$AS11,"") | E11: =IFERROR(D11/Settings!$B$8,"") | F11: =IF(D11="","",IF(D11>=Settings!$B$7,"Distinguished Learner",IF(D11>=Settings!$B$6,"Proficient Learner",IF(D11>=Settings!$B$5,"Developing Learner","Beginning Learner")))) | G11: =IF(AND(Roster!$B11<>"",COUNT('Post-Test Entry'!$C11:$AQ11)>0),'Post-Test Entry'!$AS11,"") | H11: =IFERROR(G11/Settings!$B$8,"") | I11: =IF(G11="","",IF(G11>=Settings!$B$7,"Distinguished Learner",IF(G11>=Settings!$B$6,"Proficient Learner",IF(G11>=Settings!$B$5,"Developing Learner","Beginning Learner")))) | J11: =IF(OR(D11="",G11=""),"",G11-D11) | K11: =IFERROR(IF(OR(J11="",J11<=0),"",(G11-D11)/(Settings!$B$8-D11)),"") | L11: =IFERROR(IF(J11="","",(G11-D11)/(Settings!$B$17*SQRT(2))),"") | M11: =IF(L11="","",IF(ABS(L11)>=1.96,"Yes","No")) | N11: =IF(J11="","",IF(J11>=Settings!$B$15,"Yes","No")) | O11: =IFERROR(IF($D11="","",SUMIF('Pre-Test Entry'!$C$3:$AQ$3,Settings!$A$28,'Pre-Test Entry'!$C11:$AQ11)/Settings!$C$28),"") | P11: =IFERROR(IF($D11="","",SUMIF('Pre-Test Entry'!$C$3:$AQ$3,Settings!$A$29,'Pre-Test Entry'!$C11:$AQ11)/Settings!$C$29),"") | Q11: =IFERROR(IF($D11="","",SUMIF('Pre-Test Entry'!$C$3:$AQ$3,Settings!$A$30,'Pre-Test Entry'!$C11:$AQ11)/Settings!$C$30),"") | R11: =IFERROR(IF($D11="","",SUMIF('Pre-Test Entry'!$C$3:$AQ$3,Settings!$A$31,'Pre-Test Entry'!$C11:$AQ11)/Settings!$C$31),"") | S11: =IFERROR(IF($D11="","",SUMIF('Pre-Test Entry'!$C$3:$AQ$3,Settings!$A$32,'Pre-Test Entry'!$C11:$AQ11)/Settings!$C$32),"") | T11: =IFERROR(IF($D11="","",SUMIF('Pre-Test Entry'!$C$3:$AQ$3,Settings!$A$33,'Pre-Test Entry'!$C11:$AQ11)/Settings!$C$33),"") | U11: =IFERROR(IF($D11="","",SUMIF('Pre-Test Entry'!$C$3:$AQ$3,Settings!$A$34,'Pre-Test Entry'!$C11:$AQ11)/Settings!$C$34),"") | V11: =IFERROR(IF($G11="","",SUMIF('Post-Test Entry'!$C$3:$AQ$3,Settings!$A$28,'Post-Test Entry'!$C11:$AQ11)/Settings!$C$28),"") | W11: =IFERROR(IF($G11="","",SUMIF('Post-Test Entry'!$C$3:$AQ$3,Settings!$A$29,'Post-Test Entry'!$C11:$AQ11)/Settings!$C$29),"") | X11: =IFERROR(IF($G11="","",SUMIF('Post-Test Entry'!$C$3:$AQ$3,Settings!$A$30,'Post-Test Entry'!$C11:$AQ11)/Settings!$C$30),"") | Y11: =IFERROR(IF($G11="","",SUMIF('Post-Test Entry'!$C$3:$AQ$3,Settings!$A$31,'Post-Test Entry'!$C11:$AQ11)/Settings!$C$31),"") | Z11: =IFERROR(IF($G11="","",SUMIF('Post-Test Entry'!$C$3:$AQ$3,Settings!$A$32,'Post-Test Entry'!$C11:$AQ11)/Settings!$C$32),"") | AA11: =IFERROR(IF($G11="","",SUMIF('Post-Test Entry'!$C$3:$AQ$3,Settings!$A$33,'Post-Test Entry'!$C11:$AQ11)/Settings!$C$33),"") | AB11: =IFERROR(IF($G11="","",SUMIF('Post-Test Entry'!$C$3:$AQ$3,Settings!$A$34,'Post-Test Entry'!$C11:$AQ11)/Settings!$C$34),"") | AC11: =IF(OR(O11="",V11=""),"",V11-O11) | AD11: =IF(OR(P11="",W11=""),"",W11-P11) | AE11: =IF(OR(Q11="",X11=""),"",X11-Q11) | AF11: =IF(OR(R11="",Y11=""),"",Y11-R11) | AG11: =IF(OR(S11="",Z11=""),"",Z11-S11) | AH11: =IF(OR(T11="",AA11=""),"",AA11-T11) | AI11: =IF(OR(U11="",AB11=""),"",AB11-U11) | AJ11: =IFERROR(IF($G11<>"",INDEX($V$4:$AB$4,MATCH(MIN($V11:$AB11),$V11:$AB11,0)),IF($D11<>"",INDEX($O$4:$U$4,MATCH(MIN($O11:$U11),$O11:$U11,0)),"")),"") | AK11: =IFERROR(IF($G11<>"",INDEX($V$4:$AB$4,MATCH(SMALL($V11:$AB11,2),$V11:$AB11,0)),IF($D11<>"",INDEX($O$4:$U$4,MATCH(SMALL($O11:$U11,2),$O11:$U11,0)),"")),"") | AL11: =IF(OR(G11="",Settings!$B$17=""),"",IF(OR(ABS(G11-Settings!$B$5)<=Settings!$B$17,ABS(G11-Settings!$B$6)<=Settings!$B$17,ABS(G11-Settings!$B$7)<=Settings!$B$17),"NEAR CUT","")) | AM11: =IF('Post-Test Entry'!$AR11<>"","Post essay: code "&'Post-Test Entry'!$AR11,IF('Pre-Test Entry'!$AR11<>"","Pre essay: code "&'Pre-Test Entry'!$AR11,"")) | AN11: =IFERROR(IF($AJ11="","",INDEX(Settings!$D$28:$D$34,MATCH($AJ11,Settings!$A$28:$A$34,0))),"") | AP11: =IF(D11="","",D11^2) | AQ11: =IF(G11="","",G11^2)
A12: =IF(Roster!$A12="","",Roster!$A12) | B12: =IF(Roster!$B12<>"",Roster!$C12&" "&Roster!$B12,"") | C12: =IF(Roster!$B12<>"",Roster!$D12,"") | D12: =IF(AND(Roster!$B12<>"",COUNT('Pre-Test Entry'!$C12:$AQ12)>0),'Pre-Test Entry'!$AS12,"") | E12: =IFERROR(D12/Settings!$B$8,"") | F12: =IF(D12="","",IF(D12>=Settings!$B$7,"Distinguished Learner",IF(D12>=Settings!$B$6,"Proficient Learner",IF(D12>=Settings!$B$5,"Developing Learner","Beginning Learner")))) | G12: =IF(AND(Roster!$B12<>"",COUNT('Post-Test Entry'!$C12:$AQ12)>0),'Post-Test Entry'!$AS12,"") | H12: =IFERROR(G12/Settings!$B$8,"") | I12: =IF(G12="","",IF(G12>=Settings!$B$7,"Distinguished Learner",IF(G12>=Settings!$B$6,"Proficient Learner",IF(G12>=Settings!$B$5,"Developing Learner","Beginning Learner")))) | J12: =IF(OR(D12="",G12=""),"",G12-D12) | K12: =IFERROR(IF(OR(J12="",J12<=0),"",(G12-D12)/(Settings!$B$8-D12)),"") | L12: =IFERROR(IF(J12="","",(G12-D12)/(Settings!$B$17*SQRT(2))),"") | M12: =IF(L12="","",IF(ABS(L12)>=1.96,"Yes","No")) | N12: =IF(J12="","",IF(J12>=Settings!$B$15,"Yes","No")) | O12: =IFERROR(IF($D12="","",SUMIF('Pre-Test Entry'!$C$3:$AQ$3,Settings!$A$28,'Pre-Test Entry'!$C12:$AQ12)/Settings!$C$28),"") | P12: =IFERROR(IF($D12="","",SUMIF('Pre-Test Entry'!$C$3:$AQ$3,Settings!$A$29,'Pre-Test Entry'!$C12:$AQ12)/Settings!$C$29),"") | Q12: =IFERROR(IF($D12="","",SUMIF('Pre-Test Entry'!$C$3:$AQ$3,Settings!$A$30,'Pre-Test Entry'!$C12:$AQ12)/Settings!$C$30),"") | R12: =IFERROR(IF($D12="","",SUMIF('Pre-Test Entry'!$C$3:$AQ$3,Settings!$A$31,'Pre-Test Entry'!$C12:$AQ12)/Settings!$C$31),"") | S12: =IFERROR(IF($D12="","",SUMIF('Pre-Test Entry'!$C$3:$AQ$3,Settings!$A$32,'Pre-Test Entry'!$C12:$AQ12)/Settings!$C$32),"") | T12: =IFERROR(IF($D12="","",SUMIF('Pre-Test Entry'!$C$3:$AQ$3,Settings!$A$33,'Pre-Test Entry'!$C12:$AQ12)/Settings!$C$33),"") | U12: =IFERROR(IF($D12="","",SUMIF('Pre-Test Entry'!$C$3:$AQ$3,Settings!$A$34,'Pre-Test Entry'!$C12:$AQ12)/Settings!$C$34),"") | V12: =IFERROR(IF($G12="","",SUMIF('Post-Test Entry'!$C$3:$AQ$3,Settings!$A$28,'Post-Test Entry'!$C12:$AQ12)/Settings!$C$28),"") | W12: =IFERROR(IF($G12="","",SUMIF('Post-Test Entry'!$C$3:$AQ$3,Settings!$A$29,'Post-Test Entry'!$C12:$AQ12)/Settings!$C$29),"") | X12: =IFERROR(IF($G12="","",SUMIF('Post-Test Entry'!$C$3:$AQ$3,Settings!$A$30,'Post-Test Entry'!$C12:$AQ12)/Settings!$C$30),"") | Y12: =IFERROR(IF($G12="","",SUMIF('Post-Test Entry'!$C$3:$AQ$3,Settings!$A$31,'Post-Test Entry'!$C12:$AQ12)/Settings!$C$31),"") | Z12: =IFERROR(IF($G12="","",SUMIF('Post-Test Entry'!$C$3:$AQ$3,Settings!$A$32,'Post-Test Entry'!$C12:$AQ12)/Settings!$C$32),"") | AA12: =IFERROR(IF($G12="","",SUMIF('Post-Test Entry'!$C$3:$AQ$3,Settings!$A$33,'Post-Test Entry'!$C12:$AQ12)/Settings!$C$33),"") | AB12: =IFERROR(IF($G12="","",SUMIF('Post-Test Entry'!$C$3:$AQ$3,Settings!$A$34,'Post-Test Entry'!$C12:$AQ12)/Settings!$C$34),"") | AC12: =IF(OR(O12="",V12=""),"",V12-O12) | AD12: =IF(OR(P12="",W12=""),"",W12-P12) | AE12: =IF(OR(Q12="",X12=""),"",X12-Q12) | AF12: =IF(OR(R12="",Y12=""),"",Y12-R12) | AG12: =IF(OR(S12="",Z12=""),"",Z12-S12) | AH12: =IF(OR(T12="",AA12=""),"",AA12-T12) | AI12: =IF(OR(U12="",AB12=""),"",AB12-U12) | AJ12: =IFERROR(IF($G12<>"",INDEX($V$4:$AB$4,MATCH(MIN($V12:$AB12),$V12:$AB12,0)),IF($D12<>"",INDEX($O$4:$U$4,MATCH(MIN($O12:$U12),$O12:$U12,0)),"")),"") | AK12: =IFERROR(IF($G12<>"",INDEX($V$4:$AB$4,MATCH(SMALL($V12:$AB12,2),$V12:$AB12,0)),IF($D12<>"",INDEX($O$4:$U$4,MATCH(SMALL($O12:$U12,2),$O12:$U12,0)),"")),"") | AL12: =IF(OR(G12="",Settings!$B$17=""),"",IF(OR(ABS(G12-Settings!$B$5)<=Settings!$B$17,ABS(G12-Settings!$B$6)<=Settings!$B$17,ABS(G12-Settings!$B$7)<=Settings!$B$17),"NEAR CUT","")) | AM12: =IF('Post-Test Entry'!$AR12<>"","Post essay: code "&'Post-Test Entry'!$AR12,IF('Pre-Test Entry'!$AR12<>"","Pre essay: code "&'Pre-Test Entry'!$AR12,"")) | AN12: =IFERROR(IF($AJ12="","",INDEX(Settings!$D$28:$D$34,MATCH($AJ12,Settings!$A$28:$A$34,0))),"") | AP12: =IF(D12="","",D12^2) | AQ12: =IF(G12="","",G12^2)
A13: =IF(Roster!$A13="","",Roster!$A13) | B13: =IF(Roster!$B13<>"",Roster!$C13&" "&Roster!$B13,"") | C13: =IF(Roster!$B13<>"",Roster!$D13,"") | D13: =IF(AND(Roster!$B13<>"",COUNT('Pre-Test Entry'!$C13:$AQ13)>0),'Pre-Test Entry'!$AS13,"") | E13: =IFERROR(D13/Settings!$B$8,"") | F13: =IF(D13="","",IF(D13>=Settings!$B$7,"Distinguished Learner",IF(D13>=Settings!$B$6,"Proficient Learner",IF(D13>=Settings!$B$5,"Developing Learner","Beginning Learner")))) | G13: =IF(AND(Roster!$B13<>"",COUNT('Post-Test Entry'!$C13:$AQ13)>0),'Post-Test Entry'!$AS13,"") | H13: =IFERROR(G13/Settings!$B$8,"") | I13: =IF(G13="","",IF(G13>=Settings!$B$7,"Distinguished Learner",IF(G13>=Settings!$B$6,"Proficient Learner",IF(G13>=Settings!$B$5,"Developing Learner","Beginning Learner")))) | J13: =IF(OR(D13="",G13=""),"",G13-D13) | K13: =IFERROR(IF(OR(J13="",J13<=0),"",(G13-D13)/(Settings!$B$8-D13)),"") | L13: =IFERROR(IF(J13="","",(G13-D13)/(Settings!$B$17*SQRT(2))),"") | M13: =IF(L13="","",IF(ABS(L13)>=1.96,"Yes","No")) | N13: =IF(J13="","",IF(J13>=Settings!$B$15,"Yes","No")) | O13: =IFERROR(IF($D13="","",SUMIF('Pre-Test Entry'!$C$3:$AQ$3,Settings!$A$28,'Pre-Test Entry'!$C13:$AQ13)/Settings!$C$28),"") | P13: =IFERROR(IF($D13="","",SUMIF('Pre-Test Entry'!$C$3:$AQ$3,Settings!$A$29,'Pre-Test Entry'!$C13:$AQ13)/Settings!$C$29),"") | Q13: =IFERROR(IF($D13="","",SUMIF('Pre-Test Entry'!$C$3:$AQ$3,Settings!$A$30,'Pre-Test Entry'!$C13:$AQ13)/Settings!$C$30),"") | R13: =IFERROR(IF($D13="","",SUMIF('Pre-Test Entry'!$C$3:$AQ$3,Settings!$A$31,'Pre-Test Entry'!$C13:$AQ13)/Settings!$C$31),"") | S13: =IFERROR(IF($D13="","",SUMIF('Pre-Test Entry'!$C$3:$AQ$3,Settings!$A$32,'Pre-Test Entry'!$C13:$AQ13)/Settings!$C$32),"") | T13: =IFERROR(IF($D13="","",SUMIF('Pre-Test Entry'!$C$3:$AQ$3,Settings!$A$33,'Pre-Test Entry'!$C13:$AQ13)/Settings!$C$33),"") | U13: =IFERROR(IF($D13="","",SUMIF('Pre-Test Entry'!$C$3:$AQ$3,Settings!$A$34,'Pre-Test Entry'!$C13:$AQ13)/Settings!$C$34),"") | V13: =IFERROR(IF($G13="","",SUMIF('Post-Test Entry'!$C$3:$AQ$3,Settings!$A$28,'Post-Test Entry'!$C13:$AQ13)/Settings!$C$28),"") | W13: =IFERROR(IF($G13="","",SUMIF('Post-Test Entry'!$C$3:$AQ$3,Settings!$A$29,'Post-Test Entry'!$C13:$AQ13)/Settings!$C$29),"") | X13: =IFERROR(IF($G13="","",SUMIF('Post-Test Entry'!$C$3:$AQ$3,Settings!$A$30,'Post-Test Entry'!$C13:$AQ13)/Settings!$C$30),"") | Y13: =IFERROR(IF($G13="","",SUMIF('Post-Test Entry'!$C$3:$AQ$3,Settings!$A$31,'Post-Test Entry'!$C13:$AQ13)/Settings!$C$31),"") | Z13: =IFERROR(IF($G13="","",SUMIF('Post-Test Entry'!$C$3:$AQ$3,Settings!$A$32,'Post-Test Entry'!$C13:$AQ13)/Settings!$C$32),"") | AA13: =IFERROR(IF($G13="","",SUMIF('Post-Test Entry'!$C$3:$AQ$3,Settings!$A$33,'Post-Test Entry'!$C13:$AQ13)/Settings!$C$33),"") | AB13: =IFERROR(IF($G13="","",SUMIF('Post-Test Entry'!$C$3:$AQ$3,Settings!$A$34,'Post-Test Entry'!$C13:$AQ13)/Settings!$C$34),"") | AC13: =IF(OR(O13="",V13=""),"",V13-O13) | AD13: =IF(OR(P13="",W13=""),"",W13-P13) | AE13: =IF(OR(Q13="",X13=""),"",X13-Q13) | AF13: =IF(OR(R13="",Y13=""),"",Y13-R13) | AG13: =IF(OR(S13="",Z13=""),"",Z13-S13) | AH13: =IF(OR(T13="",AA13=""),"",AA13-T13) | AI13: =IF(OR(U13="",AB13=""),"",AB13-U13) | AJ13: =IFERROR(IF($G13<>"",INDEX($V$4:$AB$4,MATCH(MIN($V13:$AB13),$V13:$AB13,0)),IF($D13<>"",INDEX($O$4:$U$4,MATCH(MIN($O13:$U13),$O13:$U13,0)),"")),"") | AK13: =IFERROR(IF($G13<>"",INDEX($V$4:$AB$4,MATCH(SMALL($V13:$AB13,2),$V13:$AB13,0)),IF($D13<>"",INDEX($O$4:$U$4,MATCH(SMALL($O13:$U13,2),$O13:$U13,0)),"")),"") | AL13: =IF(OR(G13="",Settings!$B$17=""),"",IF(OR(ABS(G13-Settings!$B$5)<=Settings!$B$17,ABS(G13-Settings!$B$6)<=Settings!$B$17,ABS(G13-Settings!$B$7)<=Settings!$B$17),"NEAR CUT","")) | AM13: =IF('Post-Test Entry'!$AR13<>"","Post essay: code "&'Post-Test Entry'!$AR13,IF('Pre-Test Entry'!$AR13<>"","Pre essay: code "&'Pre-Test Entry'!$AR13,"")) | AN13: =IFERROR(IF($AJ13="","",INDEX(Settings!$D$28:$D$34,MATCH($AJ13,Settings!$A$28:$A$34,0))),"") | AP13: =IF(D13="","",D13^2) | AQ13: =IF(G13="","",G13^2)
A14: =IF(Roster!$A14="","",Roster!$A14) | B14: =IF(Roster!$B14<>"",Roster!$C14&" "&Roster!$B14,"") | C14: =IF(Roster!$B14<>"",Roster!$D14,"") | D14: =IF(AND(Roster!$B14<>"",COUNT('Pre-Test Entry'!$C14:$AQ14)>0),'Pre-Test Entry'!$AS14,"") | E14: =IFERROR(D14/Settings!$B$8,"") | F14: =IF(D14="","",IF(D14>=Settings!$B$7,"Distinguished Learner",IF(D14>=Settings!$B$6,"Proficient Learner",IF(D14>=Settings!$B$5,"Developing Learner","Beginning Learner")))) | G14: =IF(AND(Roster!$B14<>"",COUNT('Post-Test Entry'!$C14:$AQ14)>0),'Post-Test Entry'!$AS14,"") | H14: =IFERROR(G14/Settings!$B$8,"") | I14: =IF(G14="","",IF(G14>=Settings!$B$7,"Distinguished Learner",IF(G14>=Settings!$B$6,"Proficient Learner",IF(G14>=Settings!$B$5,"Developing Learner","Beginning Learner")))) | J14: =IF(OR(D14="",G14=""),"",G14-D14) | K14: =IFERROR(IF(OR(J14="",J14<=0),"",(G14-D14)/(Settings!$B$8-D14)),"") | L14: =IFERROR(IF(J14="","",(G14-D14)/(Settings!$B$17*SQRT(2))),"") | M14: =IF(L14="","",IF(ABS(L14)>=1.96,"Yes","No")) | N14: =IF(J14="","",IF(J14>=Settings!$B$15,"Yes","No")) | O14: =IFERROR(IF($D14="","",SUMIF('Pre-Test Entry'!$C$3:$AQ$3,Settings!$A$28,'Pre-Test Entry'!$C14:$AQ14)/Settings!$C$28),"") | P14: =IFERROR(IF($D14="","",SUMIF('Pre-Test Entry'!$C$3:$AQ$3,Settings!$A$29,'Pre-Test Entry'!$C14:$AQ14)/Settings!$C$29),"") | Q14: =IFERROR(IF($D14="","",SUMIF('Pre-Test Entry'!$C$3:$AQ$3,Settings!$A$30,'Pre-Test Entry'!$C14:$AQ14)/Settings!$C$30),"") | R14: =IFERROR(IF($D14="","",SUMIF('Pre-Test Entry'!$C$3:$AQ$3,Settings!$A$31,'Pre-Test Entry'!$C14:$AQ14)/Settings!$C$31),"") | S14: =IFERROR(IF($D14="","",SUMIF('Pre-Test Entry'!$C$3:$AQ$3,Settings!$A$32,'Pre-Test Entry'!$C14:$AQ14)/Settings!$C$32),"") | T14: =IFERROR(IF($D14="","",SUMIF('Pre-Test Entry'!$C$3:$AQ$3,Settings!$A$33,'Pre-Test Entry'!$C14:$AQ14)/Settings!$C$33),"") | U14: =IFERROR(IF($D14="","",SUMIF('Pre-Test Entry'!$C$3:$AQ$3,Settings!$A$34,'Pre-Test Entry'!$C14:$AQ14)/Settings!$C$34),"") | V14: =IFERROR(IF($G14="","",SUMIF('Post-Test Entry'!$C$3:$AQ$3,Settings!$A$28,'Post-Test Entry'!$C14:$AQ14)/Settings!$C$28),"") | W14: =IFERROR(IF($G14="","",SUMIF('Post-Test Entry'!$C$3:$AQ$3,Settings!$A$29,'Post-Test Entry'!$C14:$AQ14)/Settings!$C$29),"") | X14: =IFERROR(IF($G14="","",SUMIF('Post-Test Entry'!$C$3:$AQ$3,Settings!$A$30,'Post-Test Entry'!$C14:$AQ14)/Settings!$C$30),"") | Y14: =IFERROR(IF($G14="","",SUMIF('Post-Test Entry'!$C$3:$AQ$3,Settings!$A$31,'Post-Test Entry'!$C14:$AQ14)/Settings!$C$31),"") | Z14: =IFERROR(IF($G14="","",SUMIF('Post-Test Entry'!$C$3:$AQ$3,Settings!$A$32,'Post-Test Entry'!$C14:$AQ14)/Settings!$C$32),"") | AA14: =IFERROR(IF($G14="","",SUMIF('Post-Test Entry'!$C$3:$AQ$3,Settings!$A$33,'Post-Test Entry'!$C14:$AQ14)/Settings!$C$33),"") | AB14: =IFERROR(IF($G14="","",SUMIF('Post-Test Entry'!$C$3:$AQ$3,Settings!$A$34,'Post-Test Entry'!$C14:$AQ14)/Settings!$C$34),"") | AC14: =IF(OR(O14="",V14=""),"",V14-O14) | AD14: =IF(OR(P14="",W14=""),"",W14-P14) | AE14: =IF(OR(Q14="",X14=""),"",X14-Q14) | AF14: =IF(OR(R14="",Y14=""),"",Y14-R14) | AG14: =IF(OR(S14="",Z14=""),"",Z14-S14) | AH14: =IF(OR(T14="",AA14=""),"",AA14-T14) | AI14: =IF(OR(U14="",AB14=""),"",AB14-U14) | AJ14: =IFERROR(IF($G14<>"",INDEX($V$4:$AB$4,MATCH(MIN($V14:$AB14),$V14:$AB14,0)),IF($D14<>"",INDEX($O$4:$U$4,MATCH(MIN($O14:$U14),$O14:$U14,0)),"")),"") | AK14: =IFERROR(IF($G14<>"",INDEX($V$4:$AB$4,MATCH(SMALL($V14:$AB14,2),$V14:$AB14,0)),IF($D14<>"",INDEX($O$4:$U$4,MATCH(SMALL($O14:$U14,2),$O14:$U14,0)),"")),"") | AL14: =IF(OR(G14="",Settings!$B$17=""),"",IF(OR(ABS(G14-Settings!$B$5)<=Settings!$B$17,ABS(G14-Settings!$B$6)<=Settings!$B$17,ABS(G14-Settings!$B$7)<=Settings!$B$17),"NEAR CUT","")) | AM14: =IF('Post-Test Entry'!$AR14<>"","Post essay: code "&'Post-Test Entry'!$AR14,IF('Pre-Test Entry'!$AR14<>"","Pre essay: code "&'Pre-Test Entry'!$AR14,"")) | AN14: =IFERROR(IF($AJ14="","",INDEX(Settings!$D$28:$D$34,MATCH($AJ14,Settings!$A$28:$A$34,0))),"") | AP14: =IF(D14="","",D14^2) | AQ14: =IF(G14="","",G14^2)
A15: =IF(Roster!$A15="","",Roster!$A15) | B15: =IF(Roster!$B15<>"",Roster!$C15&" "&Roster!$B15,"") | C15: =IF(Roster!$B15<>"",Roster!$D15,"") | D15: =IF(AND(Roster!$B15<>"",COUNT('Pre-Test Entry'!$C15:$AQ15)>0),'Pre-Test Entry'!$AS15,"") | E15: =IFERROR(D15/Settings!$B$8,"") | F15: =IF(D15="","",IF(D15>=Settings!$B$7,"Distinguished Learner",IF(D15>=Settings!$B$6,"Proficient Learner",IF(D15>=Settings!$B$5,"Developing Learner","Beginning Learner")))) | G15: =IF(AND(Roster!$B15<>"",COUNT('Post-Test Entry'!$C15:$AQ15)>0),'Post-Test Entry'!$AS15,"") | H15: =IFERROR(G15/Settings!$B$8,"") | I15: =IF(G15="","",IF(G15>=Settings!$B$7,"Distinguished Learner",IF(G15>=Settings!$B$6,"Proficient Learner",IF(G15>=Settings!$B$5,"Developing Learner","Beginning Learner")))) | J15: =IF(OR(D15="",G15=""),"",G15-D15) | K15: =IFERROR(IF(OR(J15="",J15<=0),"",(G15-D15)/(Settings!$B$8-D15)),"") | L15: =IFERROR(IF(J15="","",(G15-D15)/(Settings!$B$17*SQRT(2))),"") | M15: =IF(L15="","",IF(ABS(L15)>=1.96,"Yes","No")) | N15: =IF(J15="","",IF(J15>=Settings!$B$15,"Yes","No")) | O15: =IFERROR(IF($D15="","",SUMIF('Pre-Test Entry'!$C$3:$AQ$3,Settings!$A$28,'Pre-Test Entry'!$C15:$AQ15)/Settings!$C$28),"") | P15: =IFERROR(IF($D15="","",SUMIF('Pre-Test Entry'!$C$3:$AQ$3,Settings!$A$29,'Pre-Test Entry'!$C15:$AQ15)/Settings!$C$29),"") | Q15: =IFERROR(IF($D15="","",SUMIF('Pre-Test Entry'!$C$3:$AQ$3,Settings!$A$30,'Pre-Test Entry'!$C15:$AQ15)/Settings!$C$30),"") | R15: =IFERROR(IF($D15="","",SUMIF('Pre-Test Entry'!$C$3:$AQ$3,Settings!$A$31,'Pre-Test Entry'!$C15:$AQ15)/Settings!$C$31),"") | S15: =IFERROR(IF($D15="","",SUMIF('Pre-Test Entry'!$C$3:$AQ$3,Settings!$A$32,'Pre-Test Entry'!$C15:$AQ15)/Settings!$C$32),"") | T15: =IFERROR(IF($D15="","",SUMIF('Pre-Test Entry'!$C$3:$AQ$3,Settings!$A$33,'Pre-Test Entry'!$C15:$AQ15)/Settings!$C$33),"") | U15: =IFERROR(IF($D15="","",SUMIF('Pre-Test Entry'!$C$3:$AQ$3,Settings!$A$34,'Pre-Test Entry'!$C15:$AQ15)/Settings!$C$34),"") | V15: =IFERROR(IF($G15="","",SUMIF('Post-Test Entry'!$C$3:$AQ$3,Settings!$A$28,'Post-Test Entry'!$C15:$AQ15)/Settings!$C$28),"") | W15: =IFERROR(IF($G15="","",SUMIF('Post-Test Entry'!$C$3:$AQ$3,Settings!$A$29,'Post-Test Entry'!$C15:$AQ15)/Settings!$C$29),"") | X15: =IFERROR(IF($G15="","",SUMIF('Post-Test Entry'!$C$3:$AQ$3,Settings!$A$30,'Post-Test Entry'!$C15:$AQ15)/Settings!$C$30),"") | Y15: =IFERROR(IF($G15="","",SUMIF('Post-Test Entry'!$C$3:$AQ$3,Settings!$A$31,'Post-Test Entry'!$C15:$AQ15)/Settings!$C$31),"") | Z15: =IFERROR(IF($G15="","",SUMIF('Post-Test Entry'!$C$3:$AQ$3,Settings!$A$32,'Post-Test Entry'!$C15:$AQ15)/Settings!$C$32),"") | AA15: =IFERROR(IF($G15="","",SUMIF('Post-Test Entry'!$C$3:$AQ$3,Settings!$A$33,'Post-Test Entry'!$C15:$AQ15)/Settings!$C$33),"") | AB15: =IFERROR(IF($G15="","",SUMIF('Post-Test Entry'!$C$3:$AQ$3,Settings!$A$34,'Post-Test Entry'!$C15:$AQ15)/Settings!$C$34),"") | AC15: =IF(OR(O15="",V15=""),"",V15-O15) | AD15: =IF(OR(P15="",W15=""),"",W15-P15) | AE15: =IF(OR(Q15="",X15=""),"",X15-Q15) | AF15: =IF(OR(R15="",Y15=""),"",Y15-R15) | AG15: =IF(OR(S15="",Z15=""),"",Z15-S15) | AH15: =IF(OR(T15="",AA15=""),"",AA15-T15) | AI15: =IF(OR(U15="",AB15=""),"",AB15-U15) | AJ15: =IFERROR(IF($G15<>"",INDEX($V$4:$AB$4,MATCH(MIN($V15:$AB15),$V15:$AB15,0)),IF($D15<>"",INDEX($O$4:$U$4,MATCH(MIN($O15:$U15),$O15:$U15,0)),"")),"") | AK15: =IFERROR(IF($G15<>"",INDEX($V$4:$AB$4,MATCH(SMALL($V15:$AB15,2),$V15:$AB15,0)),IF($D15<>"",INDEX($O$4:$U$4,MATCH(SMALL($O15:$U15,2),$O15:$U15,0)),"")),"") | AL15: =IF(OR(G15="",Settings!$B$17=""),"",IF(OR(ABS(G15-Settings!$B$5)<=Settings!$B$17,ABS(G15-Settings!$B$6)<=Settings!$B$17,ABS(G15-Settings!$B$7)<=Settings!$B$17),"NEAR CUT","")) | AM15: =IF('Post-Test Entry'!$AR15<>"","Post essay: code "&'Post-Test Entry'!$AR15,IF('Pre-Test Entry'!$AR15<>"","Pre essay: code "&'Pre-Test Entry'!$AR15,"")) | AN15: =IFERROR(IF($AJ15="","",INDEX(Settings!$D$28:$D$34,MATCH($AJ15,Settings!$A$28:$A$34,0))),"") | AP15: =IF(D15="","",D15^2) | AQ15: =IF(G15="","",G15^2)
